2024-12-09 09:03:23,913 [Job e9820bc0-094f-4cca-b855-376417290fb4]: exception raised while executing (frappe.utils.background_jobs.execute_job)
Traceback (most recent call last):
  File "/home/erpsgt/frappe-bench/apps/frappe/frappe/model/base_document.py", line 523, in db_insert
    frappe.db.sql(
  File "/home/erpsgt/frappe-bench/apps/frappe/frappe/database/database.py", line 244, in sql
    self._cursor.execute(query, values)
  File "/home/erpsgt/frappe-bench/env/lib/python3.10/site-packages/pymysql/cursors.py", line 153, in execute
    result = self._query(query)
  File "/home/erpsgt/frappe-bench/env/lib/python3.10/site-packages/pymysql/cursors.py", line 322, in _query
    conn.query(q)
  File "/home/erpsgt/frappe-bench/env/lib/python3.10/site-packages/pymysql/connections.py", line 563, in query
    self._affected_rows = self._read_query_result(unbuffered=unbuffered)
  File "/home/erpsgt/frappe-bench/env/lib/python3.10/site-packages/pymysql/connections.py", line 825, in _read_query_result
    result.read()
  File "/home/erpsgt/frappe-bench/env/lib/python3.10/site-packages/pymysql/connections.py", line 1199, in read
    first_packet = self.connection._read_packet()
  File "/home/erpsgt/frappe-bench/env/lib/python3.10/site-packages/pymysql/connections.py", line 775, in _read_packet
    packet.raise_for_error()
  File "/home/erpsgt/frappe-bench/env/lib/python3.10/site-packages/pymysql/protocol.py", line 219, in raise_for_error
    err.raise_mysql_exception(self._data)
  File "/home/erpsgt/frappe-bench/env/lib/python3.10/site-packages/pymysql/err.py", line 150, in raise_mysql_exception
    raise errorclass(errno, errval)
pymysql.err.IntegrityError: (1062, "Duplicate entry 'ERP' for key 'PRIMARY'")

During handling of the above exception, another exception occurred:

Traceback (most recent call last):
  File "/home/erpsgt/frappe-bench/env/lib/python3.10/site-packages/rq/worker.py", line 1418, in perform_job
    rv = job.perform()
  File "/home/erpsgt/frappe-bench/env/lib/python3.10/site-packages/rq/job.py", line 1225, in perform
    self._result = self._execute()
  File "/home/erpsgt/frappe-bench/env/lib/python3.10/site-packages/rq/job.py", line 1262, in _execute
    result = self.func(*self.args, **self.kwargs)
  File "/home/erpsgt/frappe-bench/apps/frappe/frappe/utils/background_jobs.py", line 188, in execute_job
    retval = method(**kwargs)
  File "/home/erpsgt/frappe-bench/apps/frappe/frappe/core/doctype/user/user.py", line 1111, in create_contact
    contact.insert(ignore_permissions=True, ignore_links=ignore_links, ignore_mandatory=ignore_mandatory)
  File "/home/erpsgt/frappe-bench/apps/frappe/frappe/model/document.py", line 276, in insert
    self.db_insert(ignore_if_duplicate=ignore_if_duplicate)
  File "/home/erpsgt/frappe-bench/apps/frappe/frappe/model/base_document.py", line 550, in db_insert
    raise frappe.DuplicateEntryError(self.doctype, self.name, e)
frappe.exceptions.DuplicateEntryError: ('Contact', 'ERP', IntegrityError(1062, "Duplicate entry 'ERP' for key 'PRIMARY'"))

fatal: No remote configured to list refs from.
